2025-07-23 17:45:12,695 - INFO - Fetching profiles from Airtable view viwJjqdgpEfRfiE2E...
2025-07-23 17:45:12,701 - WARNING - Retrying (Retry(total=4, connect=None, read=None, redirect=None, status=None)) after connection broken by 'NewConnectionError('<urllib3.connection.HTTPSConnection object at 0x10a5d66c0>: Failed to establish a new connection: [Errno 8] nodename nor servname provided, or not known')': /v0/appqPkgB4AthfZPXh/tblyldHSbHw2QiOlT?view=viwJjqdgpEfRfiE2E
2025-07-23 17:45:12,907 - WARNING - Retrying (Retry(total=3, connect=None, read=None, redirect=None, status=None)) after connection broken by 'NewConnectionError('<urllib3.connection.HTTPSConnection object at 0x10a5d6960>: Failed to establish a new connection: [Errno 8] nodename nor servname provided, or not known')': /v0/appqPkgB4AthfZPXh/tblyldHSbHw2QiOlT?view=viwJjqdgpEfRfiE2E
2025-07-23 17:45:13,310 - WARNING - Retrying (Retry(total=2, connect=None, read=None, redirect=None, status=None)) after connection broken by 'NewConnectionError('<urllib3.connection.HTTPSConnection object at 0x10a5d6ba0>: Failed to establish a new connection: [Errno 8] nodename nor servname provided, or not known')': /v0/appqPkgB4AthfZPXh/tblyldHSbHw2QiOlT?view=viwJjqdgpEfRfiE2E
2025-07-23 17:45:14,116 - WARNING - Retrying (Retry(total=1, connect=None, read=None, redirect=None, status=None)) after connection broken by 'NewConnectionError('<urllib3.connection.HTTPSConnection object at 0x10a5d6de0>: Failed to establish a new connection: [Errno 8] nodename nor servname provided, or not known')': /v0/appqPkgB4AthfZPXh/tblyldHSbHw2QiOlT?view=viwJjqdgpEfRfiE2E
2025-07-23 17:45:15,722 - WARNING - Retrying (Retry(total=0, connect=None, read=None, redirect=None, status=None)) after connection broken by 'NewConnectionError('<urllib3.connection.HTTPSConnection object at 0x10a5d7020>: Failed to establish a new connection: [Errno 8] nodename nor servname provided, or not known')': /v0/appqPkgB4AthfZPXh/tblyldHSbHw2QiOlT?view=viwJjqdgpEfRfiE2E
2025-07-23 17:45:15,723 - ERROR - Error loading profiles from Airtable: HTTPSConnectionPool(host='api.airtable.com', port=443): Max retries exceeded with url: /v0/appqPkgB4AthfZPXh/tblyldHSbHw2QiOlT?view=viwJjqdgpEfRfiE2E (Caused by NewConnectionError('<urllib3.connection.HTTPSConnection object at 0x10a5d7260>: Failed to establish a new connection: [Errno 8] nodename nor servname provided, or not known'))
Traceback (most recent call last):
  File "/Library/Frameworks/Python.framework/Versions/3.12/lib/python3.12/site-packages/urllib3/connection.py", line 174, in _new_conn
    conn = connection.create_connection(
           ^^^^^^^^^^^^^^^^^^^^^^^^^^^^^
  File "/Library/Frameworks/Python.framework/Versions/3.12/lib/python3.12/site-packages/urllib3/util/connection.py", line 72, in create_connection
    for res in socket.getaddrinfo(host, port, family, socket.SOCK_STREAM):
               ^^^^^^^^^^^^^^^^^^^^^^^^^^^^^^^^^^^^^^^^^^^^^^^^^^^^^^^^^^
  File "/Library/Frameworks/Python.framework/Versions/3.12/lib/python3.12/socket.py", line 963, in getaddrinfo
    for res in _socket.getaddrinfo(host, port, family, type, proto, flags):
               ^^^^^^^^^^^^^^^^^^^^^^^^^^^^^^^^^^^^^^^^^^^^^^^^^^^^^^^^^^^
socket.gaierror: [Errno 8] nodename nor servname provided, or not known

During handling of the above exception, another exception occurred:

Traceback (most recent call last):
  File "/Library/Frameworks/Python.framework/Versions/3.12/lib/python3.12/site-packages/urllib3/connectionpool.py", line 716, in urlopen
    httplib_response = self._make_request(
                       ^^^^^^^^^^^^^^^^^^^
  File "/Library/Frameworks/Python.framework/Versions/3.12/lib/python3.12/site-packages/urllib3/connectionpool.py", line 404, in _make_request
    self._validate_conn(conn)
  File "/Library/Frameworks/Python.framework/Versions/3.12/lib/python3.12/site-packages/urllib3/connectionpool.py", line 1061, in _validate_conn
    conn.connect()
  File "/Library/Frameworks/Python.framework/Versions/3.12/lib/python3.12/site-packages/urllib3/connection.py", line 363, in connect
    self.sock = conn = self._new_conn()
                       ^^^^^^^^^^^^^^^^
  File "/Library/Frameworks/Python.framework/Versions/3.12/lib/python3.12/site-packages/urllib3/connection.py", line 186, in _new_conn
    raise NewConnectionError(
urllib3.exceptions.NewConnectionError: <urllib3.connection.HTTPSConnection object at 0x10a5d7260>: Failed to establish a new connection: [Errno 8] nodename nor servname provided, or not known

During handling of the above exception, another exception occurred:

Traceback (most recent call last):
  File "/Library/Frameworks/Python.framework/Versions/3.12/lib/python3.12/site-packages/requests/adapters.py", line 667, in send
    resp = conn.urlopen(
           ^^^^^^^^^^^^^
  File "/Library/Frameworks/Python.framework/Versions/3.12/lib/python3.12/site-packages/urllib3/connectionpool.py", line 830, in urlopen
    return self.urlopen(
           ^^^^^^^^^^^^^
  File "/Library/Frameworks/Python.framework/Versions/3.12/lib/python3.12/site-packages/urllib3/connectionpool.py", line 830, in urlopen
    return self.urlopen(
           ^^^^^^^^^^^^^
  File "/Library/Frameworks/Python.framework/Versions/3.12/lib/python3.12/site-packages/urllib3/connectionpool.py", line 830, in urlopen
    return self.urlopen(
           ^^^^^^^^^^^^^
  [Previous line repeated 2 more times]
  File "/Library/Frameworks/Python.framework/Versions/3.12/lib/python3.12/site-packages/urllib3/connectionpool.py", line 802, in urlopen
    retries = retries.increment(
              ^^^^^^^^^^^^^^^^^^
  File "/Library/Frameworks/Python.framework/Versions/3.12/lib/python3.12/site-packages/urllib3/util/retry.py", line 594, in increment
    raise MaxRetryError(_pool, url, error or ResponseError(cause))
urllib3.exceptions.MaxRetryError: HTTPSConnectionPool(host='api.airtable.com', port=443): Max retries exceeded with url: /v0/appqPkgB4AthfZPXh/tblyldHSbHw2QiOlT?view=viwJjqdgpEfRfiE2E (Caused by NewConnectionError('<urllib3.connection.HTTPSConnection object at 0x10a5d7260>: Failed to establish a new connection: [Errno 8] nodename nor servname provided, or not known'))

During handling of the above exception, another exception occurred:

Traceback (most recent call last):
  File "/Users/victorv/Desktop/Bot 2/dashboard_controller.py", line 926, in load_profiles
    records = table.all(view=AIRTABLE_VIEW_ID)
              ^^^^^^^^^^^^^^^^^^^^^^^^^^^^^^^^
  File "/Library/Frameworks/Python.framework/Versions/3.12/lib/python3.12/site-packages/pyairtable/api/table.py", line 260, in all
    return [record for page in self.iterate(**options) for record in page]
           ^^^^^^^^^^^^^^^^^^^^^^^^^^^^^^^^^^^^^^^^^^^^^^^^^^^^^^^^^^^^^^^
  File "/Library/Frameworks/Python.framework/Versions/3.12/lib/python3.12/site-packages/pyairtable/api/table.py", line 230, in iterate
    for page in self.api.iterate_requests(
  File "/Library/Frameworks/Python.framework/Versions/3.12/lib/python3.12/site-packages/pyairtable/api/api.py", line 336, in iterate_requests
    response = self.request(
               ^^^^^^^^^^^^^
  File "/Library/Frameworks/Python.framework/Versions/3.12/lib/python3.12/site-packages/pyairtable/api/api.py", line 268, in request
    response = self.session.send(prepared, timeout=self.timeout)
               ^^^^^^^^^^^^^^^^^^^^^^^^^^^^^^^^^^^^^^^^^^^^^^^^^
  File "/Library/Frameworks/Python.framework/Versions/3.12/lib/python3.12/site-packages/requests/sessions.py", line 703, in send
    r = adapter.send(request, **kwargs)
        ^^^^^^^^^^^^^^^^^^^^^^^^^^^^^^^
  File "/Library/Frameworks/Python.framework/Versions/3.12/lib/python3.12/site-packages/requests/adapters.py", line 700, in send
    raise ConnectionError(e, request=request)
requests.exceptions.ConnectionError: HTTPSConnectionPool(host='api.airtable.com', port=443): Max retries exceeded with url: /v0/appqPkgB4AthfZPXh/tblyldHSbHw2QiOlT?view=viwJjqdgpEfRfiE2E (Caused by NewConnectionError('<urllib3.connection.HTTPSConnection object at 0x10a5d7260>: Failed to establish a new connection: [Errno 8] nodename nor servname provided, or not known'))
2025-07-23 17:45:15,728 - ERROR - No profiles loaded!
